<?xml version="1.0"?>
<robot name="two_wheel_robot">
  <link name="base_link">
    <visual>
      <origin xyz="0 0 0.06"/>
      <geometry><box size="0.35 0.25 0.12"/></geometry>
    </visual>
    <collision>
      <origin xyz="0 0 0.06"/>
      <geometry><box size="0.35 0.25 0.12"/></geometry>
    </collision>
  </link>

  <link name="wheel_left">
    <visual>
      <origin xyz="-0.05 0.13 0.03" rpy="0 0 1.5708"/>
      <geometry><cylinder radius="0.05" length="0.02"/></geometry>
    </visual>
    <collision>
      <origin xyz="-0.05 0.13 0.03" rpy="0 0 1.5708"/>
      <geometry><cylinder radius="0.05" length="0.02"/></geometry>
    </collision>
  </link>

  <joint name="left_wheel_joint" type="continuous">
    <parent link="base_link"/>
    <child link="wheel_left"/>
    <origin xyz="-0.05 0.13 0.03"/>
    <axis xyz="0 1 0"/>
  </joint>

  <link name="wheel_right">
    <visual>
      <origin xyz="-0.05 -0.13 0.03" rpy="0 0 1.5708"/>
      <geometry><cylinder radius="0.05" length="0.02"/></geometry>
    </visual>
    <collision>
      <origin xyz="-0.05 -0.13 0.03" rpy="0 0 1.5708"/>
      <geometry><cylinder radius="0.05" length="0.02"/></geometry>
    </collision>
  </link>

  <joint name="right_wheel_joint" type="continuous">
    <parent link="base_link"/>
    <child link="wheel_right"/>
    <origin xyz="-0.05 -0.13 0.03"/>
    <axis xyz="0 1 0"/>
  </joint>
</robot>
